<?xml version="1.0" ?>
<!-- =================================================================================== -->
<!-- |    This document was autogenerated by xacro from svh_ur5_mujoco.urdf.xacro      | -->
<!-- |    EDITING THIS FILE BY HAND IS NOT RECOMMENDED                                 | -->
<!-- =================================================================================== -->
<robot name="svh">
  <mujoco>
    <compiler balanceinertia="true" discardvisual="false" meshdir="/home/francisco/catkin_ws/src/mujoco_ur5_svh_coupled/meshes"/>
  </mujoco>
  <!--
  <xacro:macro name="cylinder_inertial_fingers" params="radius length mass *origin">
    <inertial>
        <origin xyz="0 0 0" rpy="0 0 0" />
        <mass value="0.01" />
        <inertia
          ixx="0.1" ixy="0.0" ixz="0.0"
          iyy="0.1" iyz="0.0"
          izz="0.1" />
    </inertial>
  </xacro:macro>
  -->
  <gazebo>
    <plugin filename="libgazebo_ros_control.so" name="gazebo_ros_control">
      <controlPeriod>0.001</controlPeriod>
    </plugin>
  </gazebo>
  <gazebo>
    <plugin filename="libgazebo_ros_control.so" name="ros_control">
      <!--robotNamespace>/</robotNamespace-->
      <!--robotSimType>gazebo_ros_control/DefaultRobotHWSim</robotSimType-->
    </plugin>
    <!--
    <plugin name="gazebo_ros_power_monitor_controller" filename="libgazebo_ros_power_monitor.so">
      <alwaysOn>true</alwaysOn>
      <updateRate>1.0</updateRate>
      <timeout>5</timeout>
      <powerStateTopic>power_state</powerStateTopic>
      <powerStateRate>10.0</powerStateRate>
      <fullChargeCapacity>87.78</fullChargeCapacity>     
      <dischargeRate>-474</dischargeRate>
      <chargeRate>525</chargeRate>
      <dischargeVoltage>15.52</dischargeVoltage>
      <chargeVoltage>16.41</chargeVoltage>
    </plugin>
-->
  </gazebo>
  <!-- measured from model -->
  <!--property name="shoulder_height" value="0.089159" /-->
  <!--property name="shoulder_offset" value="0.13585" /-->
  <!-- shoulder_offset - elbow_offset + wrist_1_length = 0.10915 -->
  <!--property name="upper_arm_length" value="0.42500" /-->
  <!--property name="elbow_offset" value="0.1197" /-->
  <!-- CAD measured -->
  <!--property name="forearm_length" value="0.39225" /-->
  <!--property name="wrist_1_length" value="0.093" /-->
  <!-- CAD measured -->
  <!--property name="wrist_2_length" value="0.09465" /-->
  <!-- In CAD this distance is 0.930, but in the spec it is 0.09465 -->
  <!--property name="wrist_3_length" value="0.0823" /-->
  <!-- manually measured -->
  <link name="base_link">
    <visual>
      <geometry>
        <mesh filename="package://mujoco_ur5_svh_coupled/meshes/visual/base.stl"/>
      </geometry>
      <material name="LightGrey">
        <color rgba="0.7 0.7 0.7 1.0"/>
      </material>
    </visual>
    <collision>
      <geometry>
        <mesh filename="package://mujoco_ur5_svh_coupled/meshes/collision/base.stl"/>
      </geometry>
    </collision>
    <inertial>
      <mass value="4.0"/>
      <origin rpy="0 0 0" xyz="0.0 0.0 0.0"/>
      <inertia ixx="0.00443333156" ixy="0.0" ixz="0.0" iyy="0.00443333156" iyz="0.0" izz="0.0072"/>
    </inertial>
  </link>
  <joint name="shoulder_pan_joint" type="revolute">
    <parent link="base_link"/>
    <child link="shoulder_link"/>
    <origin rpy="0.0 0.0 0.0" xyz="0.0 0.0 0.089159"/>
    <axis xyz="0 0 1"/>
    <limit effort="150.0" lower="-3.141592653589793" upper="3.141592653589793" velocity="3.15"/>
    <dynamics damping="0.0" friction="0.0"/>
  </joint>
  <link name="shoulder_link">
    <visual>
      <geometry>
        <mesh filename="package://mujoco_ur5_svh_coupled/meshes/visual/shoulder.stl"/>
      </geometry>
      <material name="LightGrey">
        <color rgba="0.7 0.7 0.7 1.0"/>
      </material>
    </visual>
    <collision>
      <geometry>
        <mesh filename="package://mujoco_ur5_svh_coupled/meshes/collision/shoulder.stl"/>
      </geometry>
    </collision>
    <inertial>
      <mass value="3.7"/>
      <origin rpy="0 0 0" xyz="0.0 0.0 0.0"/>
      <inertia ixx="0.010267495893" ixy="0.0" ixz="0.0" iyy="0.010267495893" iyz="0.0" izz="0.00666"/>
    </inertial>
  </link>
  <joint name="shoulder_lift_joint" type="revolute">
    <parent link="shoulder_link"/>
    <child link="upper_arm_link"/>
    <origin rpy="0.0 1.5707963267948966 0.0" xyz="0.0 0.13585 0.0"/>
    <axis xyz="0 1 0"/>
    <limit effort="150.0" lower="-3.141592653589793" upper="3.141592653589793" velocity="3.15"/>
    <dynamics damping="0.0" friction="0.0"/>
  </joint>
  <link name="upper_arm_link">
    <visual>
      <geometry>
        <mesh filename="package://mujoco_ur5_svh_coupled/meshes/visual/upperarm.stl"/>
      </geometry>
      <material name="LightGrey">
        <color rgba="0.7 0.7 0.7 1.0"/>
      </material>
    </visual>
    <collision>
      <geometry>
        <mesh filename="package://mujoco_ur5_svh_coupled/meshes/collision/upperarm.stl"/>
      </geometry>
    </collision>
    <inertial>
      <mass value="8.393"/>
      <origin rpy="0 0 0" xyz="0.0 0.0 0.28"/>
      <inertia ixx="0.22689067591036005" ixy="0.0" ixz="0.0" iyy="0.22689067591036005" iyz="0.0" izz="0.0151074"/>
    </inertial>
  </link>
  <joint name="elbow_joint" type="revolute">
    <parent link="upper_arm_link"/>
    <child link="forearm_link"/>
    <origin rpy="0.0 0.0 0.0" xyz="0.0 -0.1197 0.425"/>
    <axis xyz="0 1 0"/>
    <limit effort="150.0" lower="-3.141592653589793" upper="3.141592653589793" velocity="3.15"/>
    <dynamics damping="0.0" friction="0.0"/>
  </joint>
  <link name="forearm_link">
    <visual>
      <geometry>
        <mesh filename="package://mujoco_ur5_svh_coupled/meshes/visual/forearm.stl"/>
      </geometry>
      <material name="LightGrey">
        <color rgba="0.7 0.7 0.7 1.0"/>
      </material>
    </visual>
    <collision>
      <geometry>
        <mesh filename="package://mujoco_ur5_svh_coupled/meshes/collision/forearm.stl"/>
      </geometry>
    </collision>
    <inertial>
      <mass value="2.275"/>
      <origin rpy="0 0 0" xyz="0.0 0.0 0.196125"/>
      <inertia ixx="0.03121679102890359" ixy="0.0" ixz="0.0" iyy="0.03121679102890359" iyz="0.0" izz="0.004095"/>
    </inertial>
  </link>
  <joint name="wrist_1_joint" type="revolute">
    <parent link="forearm_link"/>
    <child link="wrist_1_link"/>
    <origin rpy="0.0 1.5707963267948966 0.0" xyz="0.0 0.0 0.39225"/>
    <axis xyz="0 1 0"/>
    <limit effort="28.0" lower="-3.141592653589793" upper="3.141592653589793" velocity="3.2"/>
    <dynamics damping="0.0" friction="0.0"/>
  </joint>
  <link name="wrist_1_link">
    <visual>
      <geometry>
        <mesh filename="package://mujoco_ur5_svh_coupled/meshes/visual/wrist1.stl"/>
      </geometry>
      <material name="LightGrey">
        <color rgba="0.7 0.7 0.7 1.0"/>
      </material>
    </visual>
    <collision>
      <geometry>
        <mesh filename="package://mujoco_ur5_svh_coupled/meshes/collision/wrist1.stl"/>
      </geometry>
    </collision>
    <inertial>
      <mass value="1.219"/>
      <origin rpy="0 0 0" xyz="0.0 0.093 0.0"/>
      <inertia ixx="0.0025598989760400002" ixy="0.0" ixz="0.0" iyy="0.0025598989760400002" iyz="0.0" izz="0.0021942"/>
    </inertial>
  </link>
  <joint name="wrist_2_joint" type="revolute">
    <parent link="wrist_1_link"/>
    <child link="wrist_2_link"/>
    <origin rpy="0.0 0.0 0.0" xyz="0.0 0.093 0.0"/>
    <axis xyz="0 0 1"/>
    <limit effort="28.0" lower="-3.141592653589793" upper="3.141592653589793" velocity="3.2"/>
    <dynamics damping="0.0" friction="0.0"/>
  </joint>
  <link name="wrist_2_link">
    <visual>
      <geometry>
        <mesh filename="package://mujoco_ur5_svh_coupled/meshes/visual/wrist2.stl"/>
      </geometry>
      <material name="LightGrey">
        <color rgba="0.7 0.7 0.7 1.0"/>
      </material>
    </visual>
    <collision>
      <geometry>
        <mesh filename="package://mujoco_ur5_svh_coupled/meshes/collision/wrist2.stl"/>
      </geometry>
    </collision>
    <inertial>
      <mass value="1.219"/>
      <origin rpy="0 0 0" xyz="0.0 0.0 0.09465"/>
      <inertia ixx="0.0025598989760400002" ixy="0.0" ixz="0.0" iyy="0.0025598989760400002" iyz="0.0" izz="0.0021942"/>
    </inertial>
  </link>
  <joint name="wrist_3_joint" type="revolute">
    <parent link="wrist_2_link"/>
    <child link="wrist_3_link"/>
    <origin rpy="0.0 0.0 0.0" xyz="0.0 0.0 0.09465"/>
    <axis xyz="0 1 0"/>
    <limit effort="28.0" lower="-3.141592653589793" upper="3.141592653589793" velocity="3.2"/>
    <dynamics damping="0.0" friction="0.0"/>
  </joint>
  <link name="wrist_3_link">
    <visual>
      <geometry>
        <mesh filename="package://mujoco_ur5_svh_coupled/meshes/visual/wrist3.stl"/>
      </geometry>
      <material name="LightGrey">
        <color rgba="0.7 0.7 0.7 1.0"/>
      </material>
    </visual>
    <collision>
      <geometry>
        <mesh filename="package://mujoco_ur5_svh_coupled/meshes/collision/wrist3.stl"/>
      </geometry>
    </collision>
    <inertial>
      <mass value="0.1879"/>
      <origin rpy="1.5707963267948966 0 0" xyz="0.0 0.06505 0.0"/>
      <inertia ixx="8.469589112163e-05" ixy="0.0" ixz="0.0" iyy="8.469589112163e-05" iyz="0.0" izz="0.0001321171875"/>
    </inertial>
  </link>
  <joint name="ee_fixed_joint" type="fixed">
    <parent link="wrist_3_link"/>
    <child link="ee_link"/>
    <origin rpy="0.0 0.0 1.5707963267948966" xyz="0.0 0.0823 0.0"/>
  </joint>
  <link name="ee_link">
    <collision>
      <geometry>
        <box size="0.01 0.01 0.01"/>
      </geometry>
      <origin rpy="0 0 0" xyz="-0.01 0 0"/>
    </collision>
  </link>
  <transmission name="shoulder_pan_trans">
    <type>transmission_interface/SimpleTransmission</type>
    <joint name="shoulder_pan_joint">
      <hardwareInterface>hardware_interface/EffortJointInterface</hardwareInterface>
    </joint>
    <actuator name="shoulder_pan_motor">
      <mechanicalReduction>1</mechanicalReduction>
    </actuator>
  </transmission>
  <transmission name="shoulder_lift_trans">
    <type>transmission_interface/SimpleTransmission</type>
    <joint name="shoulder_lift_joint">
      <hardwareInterface>hardware_interface/EffortJointInterface</hardwareInterface>
    </joint>
    <actuator name="shoulder_lift_motor">
      <mechanicalReduction>1</mechanicalReduction>
    </actuator>
  </transmission>
  <transmission name="elbow_trans">
    <type>transmission_interface/SimpleTransmission</type>
    <joint name="elbow_joint">
      <hardwareInterface>hardware_interface/EffortJointInterface</hardwareInterface>
    </joint>
    <actuator name="elbow_motor">
      <mechanicalReduction>1</mechanicalReduction>
    </actuator>
  </transmission>
  <transmission name="wrist_1_trans">
    <type>transmission_interface/SimpleTransmission</type>
    <joint name="wrist_1_joint">
      <hardwareInterface>hardware_interface/EffortJointInterface</hardwareInterface>
    </joint>
    <actuator name="wrist_1_motor">
      <mechanicalReduction>1</mechanicalReduction>
    </actuator>
  </transmission>
  <transmission name="wrist_2_trans">
    <type>transmission_interface/SimpleTransmission</type>
    <joint name="wrist_2_joint">
      <hardwareInterface>hardware_interface/EffortJointInterface</hardwareInterface>
    </joint>
    <actuator name="wrist_2_motor">
      <mechanicalReduction>1</mechanicalReduction>
    </actuator>
  </transmission>
  <transmission name="wrist_3_trans">
    <type>transmission_interface/SimpleTransmission</type>
    <joint name="wrist_3_joint">
      <hardwareInterface>hardware_interface/EffortJointInterface</hardwareInterface>
    </joint>
    <actuator name="wrist_3_motor">
      <mechanicalReduction>1</mechanicalReduction>
    </actuator>
  </transmission>
  <gazebo reference="shoulder_link">
    <selfCollide>true</selfCollide>
  </gazebo>
  <gazebo reference="upper_arm_link">
    <selfCollide>true</selfCollide>
  </gazebo>
  <gazebo reference="forearm_link">
    <selfCollide>true</selfCollide>
  </gazebo>
  <gazebo reference="wrist_1_link">
    <selfCollide>true</selfCollide>
  </gazebo>
  <gazebo reference="wrist_3_link">
    <selfCollide>true</selfCollide>
  </gazebo>
  <gazebo reference="wrist_2_link">
    <selfCollide>true</selfCollide>
  </gazebo>
  <gazebo reference="ee_link">
    <selfCollide>true</selfCollide>
  </gazebo>
  <!-- ROS base_link to UR 'Base' Coordinates transform -->
  <link name="base"/>
  <joint name="base_link-base_fixed_joint" type="fixed">
    <!-- NOTE: this rotation is only needed as long as base_link itself is
                 not corrected wrt the real robot (ie: rotated over 180
                 degrees)
      -->
    <origin rpy="0 0 -3.141592653589793" xyz="0 0 0"/>
    <parent link="base_link"/>
    <child link="base"/>
  </joint>
  <!-- Frame coincident with all-zeros TCP on UR controller -->
  <link name="tool0"/>
  <joint name="wrist_3_link-tool0_fixed_joint" type="fixed">
    <origin rpy="-1.5707963267948966 0 0" xyz="0 0.0823 0"/>
    <parent link="wrist_3_link"/>
    <child link="tool0"/>
  </joint>
  <link name="world"/>
  <joint name="world_joint" type="fixed">
    <parent link="world"/>
    <child link="base_link"/>
    <origin rpy="0.0 0.0 0.0" xyz="0.0 0.0 0.0"/>
  </joint>
  <!-- RIGHT HAND = 1, LEFT HAND = -1 -->
  <!-- BASE_LINE LINKS -->
  <joint name="right_hand_base_joint" type="fixed">
    <origin rpy="0 0 0" xyz="0 0 0.032"/>
    <parent link="tool0"/>
    <child link="right_hand_base_link"/>
  </joint>
  <link name="right_hand_base_link">
    <origin rpy="0 0 0" xyz="0 0 0.032"/>
    <visual>
      <origin rpy="0 0 0" xyz="0 0 -0.032"/>
      <geometry>
        <mesh filename="package://mujoco_ur5_svh_coupled/meshes/base10.stl"/>
      </geometry>
    </visual>
    <collision>
      <origin rpy="0 0 0" xyz="0 0 -0.032"/>
      <geometry>
        <mesh filename="package://mujoco_ur5_svh_coupled/meshes/base10.stl"/>
      </geometry>
    </collision>
    <inertial>
      <origin rpy="0 0 0" xyz="0 0 0"/>
      <mass value="0.01"/>
      <inertia ixx="0.1" ixy="0.0" ixz="0.0" iyy="0.1" iyz="0.0" izz="0.1"/>
    </inertial>
  </link>
  <link name="right_hand_d">
    <inertial>
      <origin rpy="0 0 0" xyz="0 0 0"/>
      <mass value="0.01"/>
      <inertia ixx="0.1" ixy="0.0" ixz="0.0" iyy="0.1" iyz="0.0" izz="0.1"/>
    </inertial>
  </link>
  <link name="right_hand_h">
    <inertial>
      <origin rpy="0 0 0" xyz="0 0 0"/>
      <mass value="0.01"/>
      <inertia ixx="0.1" ixy="0.0" ixz="0.0" iyy="0.1" iyz="0.0" izz="0.1"/>
    </inertial>
  </link>
  <link name="right_hand_d2">
    <inertial>
      <origin rpy="0 0 0" xyz="0 0 0"/>
      <mass value="0.01"/>
      <inertia ixx="0.1" ixy="0.0" ixz="0.0" iyy="0.1" iyz="0.0" izz="0.1"/>
    </inertial>
  </link>
  <!-- LENGTH NOT FOUND IN DATASHEET! GUESSED!!! -->
  <link name="right_hand_e1">
    <visual>
      <origin rpy="0 0 0" xyz="0 0.01313 0"/>
      <geometry>
        <mesh filename="package://mujoco_ur5_svh_coupled/meshes/h10.stl" scale="1 1 1"/>
      </geometry>
    </visual>
    <collision>
      <origin rpy="0 0 0" xyz="0 0.01313 0"/>
      <geometry>
        <mesh filename="package://mujoco_ur5_svh_coupled/meshes/h10.stl" scale="1 1 1"/>
      </geometry>
    </collision>
    <inertial>
      <origin rpy="0 0 0" xyz="0 0 0"/>
      <mass value="0.01"/>
      <inertia ixx="0.1" ixy="0.0" ixz="0.0" iyy="0.1" iyz="0.0" izz="0.1"/>
    </inertial>
  </link>
  <!-- LENGTH NOT FOUND IN DATASHEET! GUESSED!!! -->
  <link name="right_hand_e2">
    <visual>
      <origin xyz="-0.0007 0 -0.01002"/>
      <geometry>
        <mesh filename="package://mujoco_ur5_svh_coupled/meshes/h11.stl" scale="1 1 1"/>
      </geometry>
    </visual>
    <collision>
      <origin xyz="-0.0007 0 -0.01002"/>
      <geometry>
        <mesh filename="package://mujoco_ur5_svh_coupled/meshes/h11.stl" scale="1 1 1"/>
      </geometry>
    </collision>
    <inertial>
      <origin rpy="0 0 0" xyz="0 0 0"/>
      <mass value="0.01"/>
      <inertia ixx="0.1" ixy="0.0" ixz="0.0" iyy="0.1" iyz="0.0" izz="0.1"/>
    </inertial>
  </link>
  <!-- LENGTH NOT FOUND IN DATASHEET! GUESSED!!! -->
  <link name="right_hand_e3">
    <inertial>
      <origin rpy="0 0 0" xyz="0 0 0"/>
      <mass value="0.01"/>
      <inertia ixx="0.1" ixy="0.0" ixz="0.0" iyy="0.1" iyz="0.0" izz="0.1"/>
    </inertial>
  </link>
  <link name="right_hand_e">
    <inertial>
      <origin rpy="0 0 0" xyz="0 0 0"/>
      <mass value="0.01"/>
      <inertia ixx="0.1" ixy="0.0" ixz="0.0" iyy="0.1" iyz="0.0" izz="0.1"/>
    </inertial>
  </link>
  <!-- LENGTH NOT FOUND IN DATASHEET! GUESSED, BUT POSITION CALCULATED: E4 = D-G-F!!! -->
  <link name="right_hand_e4">
    <inertial>
      <origin rpy="0 0 0" xyz="0 0 0"/>
      <mass value="0.01"/>
      <inertia ixx="0.1" ixy="0.0" ixz="0.0" iyy="0.1" iyz="0.0" izz="0.1"/>
    </inertial>
  </link>
  <!-- LENGTH NOT FOUND IN DATASHEET! GUESSED, BUT POSITION CALCULATED: E5 = D-G!!! -->
  <link name="right_hand_e5">
    <inertial>
      <origin rpy="0 0 0" xyz="0 0 0"/>
      <mass value="0.01"/>
      <inertia ixx="0.1" ixy="0.0" ixz="0.0" iyy="0.1" iyz="0.0" izz="0.1"/>
    </inertial>
  </link>
  <!-- THUMB LINKS -->
  <link name="right_hand_z">
    <visual>
      <origin xyz="0 0 0.02442"/>
      <geometry>
        <mesh filename="package://mujoco_ur5_svh_coupled/meshes/d10.stl" scale="1 1 1"/>
      </geometry>
    </visual>
    <collision>
      <origin xyz="0 0 0.02442"/>
      <geometry>
        <mesh filename="package://mujoco_ur5_svh_coupled/meshes/d10.stl" scale="1 1 1"/>
      </geometry>
    </collision>
    <inertial>
      <origin rpy="0 0 0" xyz="0 0 0"/>
      <mass value="0.01"/>
      <inertia ixx="0.1" ixy="0.0" ixz="0.0" iyy="0.1" iyz="0.0" izz="0.1"/>
    </inertial>
  </link>
  <link name="right_hand_virtual_a">
    <inertial>
      <origin rpy="0 0 0" xyz="0 0 0"/>
      <mass value="0.01"/>
      <inertia ixx="0.1" ixy="0.0" ixz="0.0" iyy="0.1" iyz="0.0" izz="0.1"/>
    </inertial>
  </link>
  <link name="right_hand_a">
    <visual>
      <geometry>
        <mesh filename="package://mujoco_ur5_svh_coupled/meshes/d11.stl" scale="1 1 1"/>
      </geometry>
    </visual>
    <collision>
      <geometry>
        <mesh filename="package://mujoco_ur5_svh_coupled/meshes/d11.stl" scale="1 1 1"/>
      </geometry>
    </collision>
    <inertial>
      <mass value="0.078"/>
      <origin rpy="0 0 0" xyz="0.0 0.0 0.0"/>
      <inertia ixx="0.1498224" ixy="0.0" ixz="0.0" iyy="0.11553615378552" iyz="0.0" izz="0.11553615378552"/>
    </inertial>
  </link>
  <link name="right_hand_b">
    <visual>
      <geometry>
        <mesh filename="package://mujoco_ur5_svh_coupled/meshes/d12.stl" scale="1 1 1"/>
      </geometry>
    </visual>
    <collision>
      <geometry>
        <mesh filename="package://mujoco_ur5_svh_coupled/meshes/d12.stl" scale="1 1 1"/>
      </geometry>
    </collision>
    <inertial>
      <mass value="0.0325"/>
      <origin rpy="0 0 0" xyz="0.0 0.0 0.0"/>
      <inertia ixx="0.062426" ixy="0.0" ixz="0.0" iyy="0.0373067350773" iyz="0.0" izz="0.0373067350773"/>
    </inertial>
  </link>
  <link name="right_hand_c">
    <visual>
      <geometry>
        <mesh filename="package://mujoco_ur5_svh_coupled/meshes/d13.stl" scale="1 1 1"/>
      </geometry>
    </visual>
    <collision>
      <geometry>
        <mesh filename="package://mujoco_ur5_svh_coupled/meshes/d13.stl" scale="1 1 1"/>
      </geometry>
      <surface>
        <friction>
          <ode>
            <mu>1</mu>
            <mu2>1</mu2>
          </ode>
        </friction>
        <contact>
          <ode>
            <min_depth>0.1</min_depth>
            <max_vel>0.0</max_vel>
          </ode>
        </contact>
      </surface>
    </collision>
    <inertial>
      <mass value="0.2"/>
      <origin rpy="0 0 0" xyz="0.0 0.0 0.0"/>
      <inertia ixx="0.38415999999999995" ixy="0.0" ixz="0.0" iyy="0.20874658316800002" iyz="0.0" izz="0.20874658316800002"/>
    </inertial>
  </link>
  <!-- INDEX FINGER LINKS -->
  <link name="right_hand_virtual_l">
    <visual>
      <origin xyz="0 0 0.01321"/>
      <geometry>
        <mesh filename="package://mujoco_ur5_svh_coupled/meshes/f10.stl"/>
      </geometry>
    </visual>
    <collision>
      <origin xyz="0 0 0.01321"/>
      <geometry>
        <mesh filename="package://mujoco_ur5_svh_coupled/meshes/f10.stl"/>
      </geometry>
    </collision>
    <inertial>
      <origin rpy="0 0 0" xyz="0 0 0"/>
      <mass value="0.01"/>
      <inertia ixx="0.1" ixy="0.0" ixz="0.0" iyy="0.1" iyz="0.0" izz="0.1"/>
    </inertial>
  </link>
  <link name="right_hand_l">
    <visual>
      <geometry>
        <mesh filename="package://mujoco_ur5_svh_coupled/meshes/f11.stl"/>
      </geometry>
    </visual>
    <collision>
      <geometry>
        <mesh filename="package://mujoco_ur5_svh_coupled/meshes/f11.stl"/>
      </geometry>
    </collision>
    <inertial>
      <mass value="0.2"/>
      <origin rpy="0 0 0" xyz="0.0 0.0 0.0"/>
      <inertia ixx="0.38415999999999995" ixy="0.0" ixz="0.0" iyy="0.342079863168" iyz="0.0" izz="0.342079863168"/>
    </inertial>
  </link>
  <link name="right_hand_p">
    <visual>
      <geometry>
        <mesh filename="package://mujoco_ur5_svh_coupled/meshes/f12.stl"/>
      </geometry>
    </visual>
    <collision>
      <geometry>
        <mesh filename="package://mujoco_ur5_svh_coupled/meshes/f12.stl"/>
      </geometry>
    </collision>
    <inertial>
      <mass value="0.2"/>
      <origin rpy="0 0 0" xyz="0.0 0.0 0.0"/>
      <inertia ixx="0.38415999999999995" ixy="0.0" ixz="0.0" iyy="0.25874656316800004" iyz="0.0" izz="0.25874656316800004"/>
    </inertial>
  </link>
  <link name="right_hand_t">
    <visual>
      <geometry>
        <mesh filename="package://mujoco_ur5_svh_coupled/meshes/f13.stl"/>
      </geometry>
    </visual>
    <collision name="index_collision">
      <geometry>
        <mesh filename="package://mujoco_ur5_svh_coupled/meshes/f13.stl"/>
      </geometry>
      <surface>
        <friction>
          <ode>
            <mu>1</mu>
            <mu2>1</mu2>
          </ode>
        </friction>
        <contact>
          <ode>
            <min_depth>0.1</min_depth>
            <max_vel>0.0</max_vel>
          </ode>
        </contact>
      </surface>
    </collision>
    <inertial>
      <mass value="0.2"/>
      <origin rpy="0 0 0" xyz="0.0 0.0 0.0"/>
      <inertia ixx="0.38415999999999995" ixy="0.0" ixz="0.0" iyy="0.229579908168" iyz="0.0" izz="0.229579908168"/>
    </inertial>
  </link>
  <!-- MIDDLE FINGER LINKS -->
  <link name="right_hand_virtual_k">
    <visual>
      <origin xyz="0 0 0.01321"/>
      <geometry>
        <mesh filename="package://mujoco_ur5_svh_coupled/meshes/f20.stl"/>
      </geometry>
    </visual>
    <collision>
      <origin xyz="0 0 0.01321"/>
      <geometry>
        <mesh filename="package://mujoco_ur5_svh_coupled/meshes/f20.stl"/>
      </geometry>
    </collision>
    <inertial>
      <origin rpy="0 0 0" xyz="0 0 0"/>
      <mass value="0.01"/>
      <inertia ixx="0.1" ixy="0.0" ixz="0.0" iyy="0.1" iyz="0.0" izz="0.1"/>
    </inertial>
  </link>
  <link name="right_hand_k">
    <visual>
      <geometry>
        <mesh filename="package://mujoco_ur5_svh_coupled/meshes/f21.stl"/>
      </geometry>
    </visual>
    <collision>
      <geometry>
        <mesh filename="package://mujoco_ur5_svh_coupled/meshes/f21.stl"/>
      </geometry>
    </collision>
    <inertial>
      <mass value="0.078"/>
      <origin rpy="0 0 0" xyz="0.0 0.0 0.0"/>
      <inertia ixx="0.1498224" ixy="0.0" ixz="0.0" iyy="0.15453613818552" iyz="0.0" izz="0.15453613818552"/>
    </inertial>
  </link>
  <link name="right_hand_o">
    <visual>
      <geometry>
        <mesh filename="package://mujoco_ur5_svh_coupled/meshes/f22.stl"/>
      </geometry>
    </visual>
    <collision>
      <geometry>
        <mesh filename="package://mujoco_ur5_svh_coupled/meshes/f22.stl"/>
      </geometry>
    </collision>
    <inertial>
      <mass value="0.0325"/>
      <origin rpy="0 0 0" xyz="0.0 0.0 0.0"/>
      <inertia ixx="0.062426" ixy="0.0" ixz="0.0" iyy="0.0420463165148" iyz="0.0" izz="0.0420463165148"/>
    </inertial>
  </link>
  <link name="right_hand_s">
    <visual>
      <geometry>
        <mesh filename="package://mujoco_ur5_svh_coupled/meshes/f23.stl"/>
      </geometry>
    </visual>
    <collision>
      <geometry>
        <mesh filename="package://mujoco_ur5_svh_coupled/meshes/f23.stl"/>
      </geometry>
      <surface>
        <friction>
          <ode>
            <mu>1</mu>
            <mu2>1</mu2>
          </ode>
        </friction>
        <contact>
          <ode>
            <min_depth>0.1</min_depth>
            <max_vel>0.0</max_vel>
          </ode>
        </contact>
      </surface>
    </collision>
    <inertial>
      <mass value="0.0195"/>
      <origin rpy="0 0 0" xyz="0.0 0.0 0.0"/>
      <inertia ixx="0.0374556" ixy="0.0" ixz="0.0" iyy="0.022384041046379997" iyz="0.0" izz="0.022384041046379997"/>
    </inertial>
  </link>
  <!-- RING FINGER LINKS -->
  <link name="right_hand_virtual_j">
    <visual>
      <origin xyz="0 0 -0.01321"/>
      <geometry>
        <mesh filename="package://mujoco_ur5_svh_coupled/meshes/f30.stl"/>
      </geometry>
    </visual>
    <collision>
      <origin xyz="0 0 -0.01321"/>
      <geometry>
        <mesh filename="package://mujoco_ur5_svh_coupled/meshes/f30.stl"/>
      </geometry>
    </collision>
    <inertial>
      <origin rpy="0 0 0" xyz="0 0 0"/>
      <mass value="0.01"/>
      <inertia ixx="0.1" ixy="0.0" ixz="0.0" iyy="0.1" iyz="0.0" izz="0.1"/>
    </inertial>
  </link>
  <link name="right_hand_j">
    <visual>
      <geometry>
        <mesh filename="package://mujoco_ur5_svh_coupled/meshes/f31.stl"/>
      </geometry>
    </visual>
    <collision>
      <geometry>
        <mesh filename="package://mujoco_ur5_svh_coupled/meshes/f31.stl"/>
      </geometry>
    </collision>
    <inertial>
      <mass value="0.078"/>
      <origin rpy="0 0 0" xyz="0.0 0.0 0.0"/>
      <inertia ixx="0.1498224" ixy="0.0" ixz="0.0" iyy="0.15453613818552" iyz="0.0" izz="0.15453613818552"/>
    </inertial>
  </link>
  <link name="right_hand_n">
    <visual>
      <geometry>
        <mesh filename="package://mujoco_ur5_svh_coupled/meshes/f32.stl"/>
      </geometry>
    </visual>
    <collision>
      <geometry>
        <mesh filename="package://mujoco_ur5_svh_coupled/meshes/f32.stl"/>
      </geometry>
    </collision>
    <inertial>
      <mass value="0.0325"/>
      <origin rpy="0 0 0" xyz="0.0 0.0 0.0"/>
      <inertia ixx="0.062426" ixy="0.0" ixz="0.0" iyy="0.0420463165148" iyz="0.0" izz="0.0420463165148"/>
    </inertial>
  </link>
  <link name="right_hand_r">
    <visual>
      <geometry>
        <mesh filename="package://mujoco_ur5_svh_coupled/meshes/f33.stl"/>
      </geometry>
    </visual>
    <collision>
      <geometry>
        <mesh filename="package://mujoco_ur5_svh_coupled/meshes/f33.stl"/>
      </geometry>
      <surface>
        <friction>
          <ode>
            <mu>1</mu>
            <mu2>1</mu2>
          </ode>
        </friction>
        <contact>
          <ode>
            <min_depth>0.1</min_depth>
            <max_vel>0.0</max_vel>
          </ode>
        </contact>
      </surface>
    </collision>
    <inertial>
      <mass value="0.0195"/>
      <origin rpy="0 0 0" xyz="0.0 0.0 0.0"/>
      <inertia ixx="0.0374556" ixy="0.0" ixz="0.0" iyy="0.022384041046379997" iyz="0.0" izz="0.022384041046379997"/>
    </inertial>
  </link>
  <!-- LITTLE FINGER LINKS -->
  <link name="right_hand_virtual_i">
    <visual>
      <origin xyz="0 0 -0.01321"/>
      <geometry>
        <mesh filename="package://mujoco_ur5_svh_coupled/meshes/f40.stl"/>
      </geometry>
    </visual>
    <collision>
      <origin xyz="0 0 -0.01321"/>
      <geometry>
        <mesh filename="package://mujoco_ur5_svh_coupled/meshes/f40.stl"/>
      </geometry>
    </collision>
    <inertial>
      <origin rpy="0 0 0" xyz="0 0 0"/>
      <mass value="0.01"/>
      <inertia ixx="0.1" ixy="0.0" ixz="0.0" iyy="0.1" iyz="0.0" izz="0.1"/>
    </inertial>
  </link>
  <link name="right_hand_i">
    <visual>
      <geometry>
        <mesh filename="package://mujoco_ur5_svh_coupled/meshes/f41.stl"/>
      </geometry>
    </visual>
    <collision>
      <geometry>
        <mesh filename="package://mujoco_ur5_svh_coupled/meshes/f41.stl"/>
      </geometry>
    </collision>
    <inertial>
      <mass value="0.078"/>
      <origin rpy="0 0 0" xyz="0.0 0.0 0.0"/>
      <inertia ixx="0.1498224" ixy="0.0" ixz="0.0" iyy="0.15453613818552" iyz="0.0" izz="0.15453613818552"/>
    </inertial>
  </link>
  <link name="right_hand_m">
    <visual>
      <geometry>
        <mesh filename="package://mujoco_ur5_svh_coupled/meshes/f42.stl"/>
      </geometry>
    </visual>
    <collision>
      <geometry>
        <mesh filename="package://mujoco_ur5_svh_coupled/meshes/f42.stl"/>
      </geometry>
    </collision>
    <inertial>
      <mass value="0.0325"/>
      <origin rpy="0 0 0" xyz="0.0 0.0 0.0"/>
      <inertia ixx="0.062426" ixy="0.0" ixz="0.0" iyy="0.0420463165148" iyz="0.0" izz="0.0420463165148"/>
    </inertial>
  </link>
  <link name="right_hand_q">
    <visual>
      <geometry>
        <mesh filename="package://mujoco_ur5_svh_coupled/meshes/f43.stl"/>
      </geometry>
    </visual>
    <collision>
      <geometry>
        <mesh filename="package://mujoco_ur5_svh_coupled/meshes/f43.stl"/>
      </geometry>
      <surface>
        <friction>
          <ode>
            <mu>1</mu>
            <mu2>1</mu2>
          </ode>
        </friction>
        <contact>
          <ode>
            <min_depth>0.1</min_depth>
            <max_vel>0.0</max_vel>
          </ode>
        </contact>
      </surface>
    </collision>
    <inertial>
      <mass value="0.0195"/>
      <origin rpy="0 0 0" xyz="0.0 0.0 0.0"/>
      <inertia ixx="0.0374556" ixy="0.0" ixz="0.0" iyy="0.022384041046379997" iyz="0.0" izz="0.022384041046379997"/>
    </inertial>
  </link>
  <joint name="right_hand_Thumb_Flexion" type="revolute">
    <parent link="right_hand_virtual_a"/>
    <child link="right_hand_a"/>
    <limit effort="10.0" lower="0.0" upper="0.9704" velocity="1"/>
    <origin rpy="0 0 -0.9704" xyz="0 0 0"/>
    <axis xyz="0 0 1"/>
    <dynamics damping="50.5" friction="1"/>
  </joint>
  <joint name="right_hand_Thumb_Helper" type="fixed">
    <parent link="right_hand_z"/>
    <child link="right_hand_virtual_a"/>
    <origin rpy="0 -1.5707 3.1416" xyz="0 0 0.04596"/>
  </joint>
  <!-- BASE_LINE JOINTS -->
  <joint name="right_hand_Thumb_Opposition" type="revolute">
    <parent link="right_hand_e1"/>
    <child link="right_hand_z"/>
    <limit effort="10.0" lower="0.0" upper="0.9879" velocity="1"/>
    <origin rpy="0 0.2618 1.571" xyz="-0.0169 0.02626 0"/>
    <axis xyz="0 0 -1"/>
    <dynamics damping="50.5" friction="1"/>
  </joint>
  <!-- JOINT NOT FOR BASE_LINE. BUT WRITTEN DOWN HERE FOR BETTER UX -->
  <joint name="right_hand_f1" type="fixed">
    <parent link="right_hand_e1"/>
    <child link="right_hand_d"/>
    <origin rpy="0 0 0" xyz="0 0 0"/>
  </joint>
  <joint name="right_hand_f2" type="fixed">
    <parent link="right_hand_d"/>
    <child link="right_hand_h"/>
    <origin rpy="0 0 0" xyz="0 0 0"/>
  </joint>
  <joint name="right_hand_f3" type="fixed">
    <parent link="right_hand_h"/>
    <child link="right_hand_d2"/>
    <origin rpy="0 0 0" xyz="0 0 0"/>
  </joint>
  <joint name="right_hand_f4" type="fixed">
    <parent link="right_hand_base_link"/>
    <child link="right_hand_e1"/>
    <origin rpy="0 0 0" xyz="0 -0.01313 0"/>
  </joint>
  <joint name="right_hand_j5" type="revolute">
    <parent link="right_hand_e1"/>
    <child link="right_hand_e2"/>
    <limit effort="10.0" lower="0.0" upper="0.98786" velocity="1"/>
    <origin rpy="0 0 0" xyz="0.0184 0.006 0.0375"/>
    <axis xyz="0 0 1"/>
    <mimic joint="right_hand_Thumb_Opposition" multiplier="1" offset="0"/>
    <dynamics damping="50.5" friction="1"/>
  </joint>
  <gazebo>
    <plugin filename="libroboticsgroup_upatras_gazebo_mimic_joint_plugin.so" name="right_hand_j5_mimic_joint_plugin">
      <joint>right_hand_Thumb_Opposition</joint>
      <mimicJoint>right_hand_j5</mimicJoint>
      <multiplier>1</multiplier>
      <offset>0</offset>
      <sensitiveness>0.0</sensitiveness>
      <!-- if absolute difference between setpoint and process value is below this threshold, do nothing; 0.0 = disable [rad] -->
      <maxEffort>10.0</maxEffort>
    </plugin>
  </gazebo>
  <joint name="right_hand_f5" type="fixed">
    <parent link="right_hand_e2"/>
    <child link="right_hand_e3"/>
    <origin rpy="0 0 0" xyz="0 -0.0060 0"/>
  </joint>
  <joint name="right_hand_f6" type="fixed">
    <parent link="right_hand_e3"/>
    <child link="right_hand_e"/>
    <origin rpy="0 0 0" xyz="0 0 0"/>
  </joint>
  <joint name="right_hand_f7" type="fixed">
    <parent link="right_hand_e"/>
    <child link="right_hand_e4"/>
    <origin rpy="0 0 0" xyz="0 0 0"/>
  </joint>
  <joint name="right_hand_f8" type="fixed">
    <parent link="right_hand_e"/>
    <child link="right_hand_e5"/>
    <origin rpy="0 0 0" xyz="0 0 0"/>
  </joint>
  <!-- THUMB JOINTS -->
  <joint name="right_hand_j3" type="revolute">
    <parent link="right_hand_a"/>
    <child link="right_hand_b"/>
    <limit effort="10.0" lower="0.0" upper="0.98506" velocity="1"/>
    <origin rpy="0 0 0" xyz="0.0485 0 0"/>
    <axis xyz="0 0 1"/>
    <mimic joint="right_hand_Thumb_Flexion" multiplier="1.01511" offset="0"/>
    <dynamics damping="50.5" friction="1"/>
  </joint>
  <gazebo>
    <plugin filename="libroboticsgroup_upatras_gazebo_mimic_joint_plugin.so" name="right_hand_j3_mimic_joint_plugin">
      <joint>right_hand_Thumb_Flexion</joint>
      <mimicJoint>right_hand_j3</mimicJoint>
      <multiplier>1.01511</multiplier>
      <offset>0</offset>
      <sensitiveness>0.0</sensitiveness>
      <!-- if absolute difference between setpoint and process value is below this threshold, do nothing; 0.0 = disable [rad] -->
      <maxEffort>10.0</maxEffort>
    </plugin>
  </gazebo>
  <joint name="right_hand_j4" type="revolute">
    <parent link="right_hand_b"/>
    <child link="right_hand_c"/>
    <limit effort="10.0" lower="0.0" upper="1.406" velocity="1"/>
    <origin rpy="0 0 0" xyz="0.030 0 0"/>
    <axis xyz="0 0 1"/>
    <mimic joint="right_hand_Thumb_Flexion" multiplier="1.44889" offset="0"/>
    <dynamics damping="50.5" friction="1"/>
  </joint>
  <gazebo>
    <plugin filename="libroboticsgroup_upatras_gazebo_mimic_joint_plugin.so" name="right_hand_j4_mimic_joint_plugin">
      <joint>right_hand_Thumb_Flexion</joint>
      <mimicJoint>right_hand_j4</mimicJoint>
      <multiplier>1.44889</multiplier>
      <offset>0</offset>
      <sensitiveness>0.0</sensitiveness>
      <!-- if absolute difference between setpoint and process value is below this threshold, do nothing; 0.0 = disable [rad] -->
      <maxEffort>10.0</maxEffort>
    </plugin>
  </gazebo>
  <!-- INDEX FINGER JOINTS -->
  <joint name="right_hand_Index_Finger_Distal" type="revolute">
    <parent link="right_hand_l"/>
    <child link="right_hand_p"/>
    <limit effort="10.0" lower="0" upper="1.334" velocity="1"/>
    <origin rpy="0 0 0" xyz="0.04804 0 0"/>
    <axis xyz="0 0 1"/>
    <dynamics damping="50.5" friction="1"/>
  </joint>
  <joint name="right_hand_Index_Finger_Proximal" type="revolute">
    <parent link="right_hand_virtual_l"/>
    <child link="right_hand_l"/>
    <limit effort="10.0" lower="0.0" upper="0.79849" velocity="1"/>
    <origin rpy="-1.5707 0 0" xyz="0 0 0"/>
    <axis xyz="0 0 1"/>
    <dynamics damping="50.5" friction="1"/>
  </joint>
  <!-- JOINT Finger_Spread in BASE_LINE section for better UX -->
  <joint name="right_hand_j14" type="revolute">
    <parent link="right_hand_p"/>
    <child link="right_hand_t"/>
    <limit effort="10.0" lower="0" upper="1.394" velocity="1"/>
    <origin rpy="0 0 0" xyz="0.026 0 0"/>
    <axis xyz="0 0 1"/>
    <mimic joint="right_hand_Index_Finger_Distal" multiplier="1.0450" offset="0"/>
    <dynamics damping="50.5" friction="1"/>
  </joint>
  <gazebo>
    <plugin filename="libroboticsgroup_upatras_gazebo_mimic_joint_plugin.so" name="right_hand_j14_mimic_joint_plugin">
      <joint>right_hand_Index_Finger_Distal</joint>
      <mimicJoint>right_hand_j14</mimicJoint>
      <multiplier>1.045</multiplier>
      <offset>0</offset>
      <sensitiveness>0.0</sensitiveness>
      <!-- if absolute difference between setpoint and process value is below this threshold, do nothing; 0.0 = disable [rad] -->
      <maxEffort>10.0</maxEffort>
    </plugin>
  </gazebo>
  <!-- MIDDLE FINGER JOINTS -->
  <joint name="right_hand_Middle_Finger_Proximal" type="revolute">
    <parent link="right_hand_virtual_k"/>
    <child link="right_hand_k"/>
    <limit effort="10.0" lower="0.0" upper="0.79849" velocity="1"/>
    <origin rpy="-1.5707 0 0" xyz="0 0 0"/>
    <axis xyz="0 0 1"/>
    <dynamics damping="50.5" friction="1"/>
  </joint>
  <joint name="right_hand_Middle_Finger_Distal" type="revolute">
    <parent link="right_hand_k"/>
    <child link="right_hand_o"/>
    <limit effort="10.0" lower="0" upper="1.334" velocity="1"/>
    <origin rpy="0 0 0" xyz="0.05004 0 0"/>
    <axis xyz="0 0 1"/>
    <dynamics damping="50.5" friction="1"/>
  </joint>
  <joint name="right_hand_j15" type="revolute">
    <parent link="right_hand_o"/>
    <child link="right_hand_s"/>
    <limit effort="10.0" lower="0" upper="1.334" velocity="1"/>
    <origin rpy="0 0 0" xyz="0.032 0 0"/>
    <axis xyz="0 0 1"/>
    <mimic joint="right_hand_Middle_Finger_Distal" multiplier="1.0454" offset="0"/>
    <dynamics damping="50.5" friction="1"/>
  </joint>
  <gazebo>
    <plugin filename="libroboticsgroup_upatras_gazebo_mimic_joint_plugin.so" name="right_hand_j15_mimic_joint_plugin">
      <joint>right_hand_Middle_Finger_Distal</joint>
      <mimicJoint>right_hand_j15</mimicJoint>
      <multiplier>1.0454</multiplier>
      <offset>0</offset>
      <sensitiveness>0.0</sensitiveness>
      <!-- if absolute difference between setpoint and process value is below this threshold, do nothing; 0.0 = disable [rad] -->
      <maxEffort>10.0</maxEffort>
    </plugin>
  </gazebo>
  <!-- RING FINGER JOINTS -->
  <joint name="right_hand_Ring_Finger" type="revolute">
    <parent link="right_hand_virtual_j"/>
    <child link="right_hand_j"/>
    <limit effort="10.0" lower="0.0" upper="0.98175" velocity="1"/>
    <origin rpy="1.5707 0 0" xyz="0 0 0"/>
    <axis xyz="0 0 1"/>
    <dynamics damping="50.5" friction="1"/>
  </joint>
  <joint name="right_hand_j12" type="revolute">
    <parent link="right_hand_j"/>
    <child link="right_hand_n"/>
    <limit effort="10.0" lower="0" upper="1.334" velocity="1"/>
    <origin rpy="0 0 0" xyz="0.05004 0 0"/>
    <axis xyz="0 0 1"/>
    <mimic joint="right_hand_Ring_Finger" multiplier="1.3588" offset="0"/>
    <dynamics damping="50.5" friction="1"/>
  </joint>
  <gazebo>
    <plugin filename="libroboticsgroup_upatras_gazebo_mimic_joint_plugin.so" name="right_hand_j12_mimic_joint_plugin">
      <joint>right_hand_Ring_Finger</joint>
      <mimicJoint>right_hand_j12</mimicJoint>
      <multiplier>1.3588</multiplier>
      <offset>0</offset>
      <sensitiveness>0.0</sensitiveness>
      <!-- if absolute difference between setpoint and process value is below this threshold, do nothing; 0.0 = disable [rad] -->
      <maxEffort>10.0</maxEffort>
    </plugin>
  </gazebo>
  <joint name="right_hand_j16" type="revolute">
    <parent link="right_hand_n"/>
    <child link="right_hand_r"/>
    <limit effort="10.0" lower="0" upper="1.395" velocity="1"/>
    <origin rpy="0 0 0" xyz="0.032 0 0"/>
    <axis xyz="0 0 1"/>
    <mimic joint="right_hand_Ring_Finger" multiplier="1.42093" offset="0"/>
    <dynamics damping="50.5" friction="1"/>
  </joint>
  <gazebo>
    <plugin filename="libroboticsgroup_upatras_gazebo_mimic_joint_plugin.so" name="right_hand_j16_mimic_joint_plugin">
      <joint>right_hand_Ring_Finger</joint>
      <mimicJoint>right_hand_j16</mimicJoint>
      <multiplier>1.42093</multiplier>
      <offset>0</offset>
      <sensitiveness>0.0</sensitiveness>
      <!-- if absolute difference between setpoint and process value is below this threshold, do nothing; 0.0 = disable [rad] -->
      <maxEffort>10.0</maxEffort>
    </plugin>
  </gazebo>
  <!-- PINKY JOINTS -->
  <joint name="right_hand_Pinky" type="revolute">
    <parent link="right_hand_virtual_i"/>
    <child link="right_hand_i"/>
    <limit effort="10.0" lower="0.0" upper="0.98175" velocity="1"/>
    <origin rpy="1.5707 0 0" xyz="0 0 0"/>
    <axis xyz="0 0 1"/>
    <dynamics damping="50.5" friction="1"/>
  </joint>
  <joint name="right_hand_j13" type="revolute">
    <parent link="right_hand_i"/>
    <child link="right_hand_m"/>
    <limit effort="10.0" lower="0" upper="1.334" velocity="1"/>
    <origin rpy="0 0 0" xyz="0.04454 0 0"/>
    <axis xyz="0 0 1"/>
    <mimic joint="right_hand_Pinky" multiplier="1.35880" offset="0"/>
    <dynamics damping="50.5" friction="1"/>
  </joint>
  <gazebo>
    <plugin filename="libroboticsgroup_upatras_gazebo_mimic_joint_plugin.so" name="right_hand_j13_mimic_joint_plugin">
      <joint>right_hand_Pinky</joint>
      <mimicJoint>right_hand_j13</mimicJoint>
      <multiplier>1.3588</multiplier>
      <offset>0</offset>
      <sensitiveness>0.0</sensitiveness>
      <!-- if absolute difference between setpoint and process value is below this threshold, do nothing; 0.0 = disable [rad] -->
      <maxEffort>10.0</maxEffort>
    </plugin>
  </gazebo>
  <joint name="right_hand_j17" type="revolute">
    <parent link="right_hand_m"/>
    <child link="right_hand_q"/>
    <limit effort="10.0" lower="0" upper="1.3971" velocity="1"/>
    <origin rpy="0 0 0" xyz="0.022 0 0"/>
    <axis xyz="0 0 1"/>
    <mimic joint="right_hand_Pinky" multiplier="1.42307" offset="0"/>
    <dynamics damping="50.5" friction="1"/>
  </joint>
  <gazebo>
    <plugin filename="libroboticsgroup_upatras_gazebo_mimic_joint_plugin.so" name="right_hand_j17_mimic_joint_plugin">
      <joint>right_hand_Pinky</joint>
      <mimicJoint>right_hand_j17</mimicJoint>
      <multiplier>1.42307</multiplier>
      <offset>0</offset>
      <sensitiveness>0.0</sensitiveness>
      <!-- if absolute difference between setpoint and process value is below this threshold, do nothing; 0.0 = disable [rad] -->
      <maxEffort>10.0</maxEffort>
    </plugin>
  </gazebo>
  <joint name="right_hand_index_spread" type="revolute">
    <parent link="right_hand_d2"/>
    <child link="right_hand_virtual_l"/>
    <limit effort="10.0" lower="0.0" upper="0.28833" velocity="1"/>
    <origin rpy="0 -1.5707 1.5707" xyz="-0.025 0 0.110"/>
    <axis xyz="0 0 1"/>
    <mimic joint="right_hand_Finger_Spread" multiplier="0.5" offset="0"/>
    <dynamics damping="50.5" friction="1"/>
  </joint>
  <gazebo>
    <plugin filename="libroboticsgroup_upatras_gazebo_mimic_joint_plugin.so" name="right_hand_index_spread_mimic_joint_plugin">
      <joint>right_hand_Finger_Spread</joint>
      <mimicJoint>right_hand_index_spread</mimicJoint>
      <multiplier>0.5</multiplier>
      <offset>0</offset>
      <sensitiveness>0.0</sensitiveness>
      <!-- if absolute difference between setpoint and process value is below this threshold, do nothing; 0.0 = disable [rad] -->
      <maxEffort>10.0</maxEffort>
    </plugin>
  </gazebo>
  <joint name="right_hand_middle_spread_dummy" type="fixed">
    <parent link="right_hand_d"/>
    <child link="right_hand_virtual_k"/>
    <origin rpy="0 -1.5707 1.5707" xyz="0 0 0.110"/>
  </joint>
  <joint name="right_hand_ring_spread" type="revolute">
    <parent link="right_hand_e5"/>
    <child link="right_hand_virtual_j"/>
    <limit effort="10.0" lower="0.0" upper="0.28833" velocity="1"/>
    <origin rpy="-1.5707 -1.5707 0" xyz="0.003855 0 0.0655"/>
    <axis xyz="0 0 1"/>
    <mimic joint="right_hand_Finger_Spread" multiplier="0.5" offset="0"/>
    <dynamics damping="50.5" friction="1"/>
  </joint>
  <gazebo>
    <plugin filename="libroboticsgroup_upatras_gazebo_mimic_joint_plugin.so" name="right_hand_ring_spread_mimic_joint_plugin">
      <joint>right_hand_Finger_Spread</joint>
      <mimicJoint>right_hand_ring_spread</mimicJoint>
      <multiplier>0.5</multiplier>
      <offset>0</offset>
      <sensitiveness>0.0</sensitiveness>
      <!-- if absolute difference between setpoint and process value is below this threshold, do nothing; 0.0 = disable [rad] -->
      <maxEffort>10.0</maxEffort>
    </plugin>
  </gazebo>
  <joint name="right_hand_Finger_Spread" type="revolute">
    <parent link="right_hand_e4"/>
    <child link="right_hand_virtual_i"/>
    <limit effort="10.0" lower="0.0" upper="0.5829" velocity="1"/>
    <origin rpy="-1.5707 -1.5707 0" xyz="0.025355 0 0.056"/>
    <axis xyz="0 0 1"/>
    <dynamics damping="50.5" friction="1"/>
  </joint>
  <!-- Transmissions -->
  <transmission name="thumb_flexion_trans">
    <type>transmission_interface/SimpleTransmission</type>
    <joint name="right_hand_Thumb_Flexion">
      <hardwareInterface>hardware_interface/EffortJointInterface</hardwareInterface>
    </joint>
    <actuator name="thumb_flexion_motor">
      <mechanicalReduction>1</mechanicalReduction>
    </actuator>
  </transmission>
  <transmission name="thumb_opposition_trans">
    <type>transmission_interface/SimpleTransmission</type>
    <joint name="right_hand_Thumb_Opposition">
      <hardwareInterface>hardware_interface/EffortJointInterface</hardwareInterface>
    </joint>
    <actuator name="thumb_opposition_motor">
      <mechanicalReduction>1</mechanicalReduction>
    </actuator>
  </transmission>
  <transmission name="index_distal_trans">
    <type>transmission_interface/SimpleTransmission</type>
    <joint name="right_hand_Index_Finger_Distal">
      <hardwareInterface>hardware_interface/EffortJointInterface</hardwareInterface>
    </joint>
    <actuator name="index_distal_motor">
      <mechanicalReduction>1</mechanicalReduction>
    </actuator>
  </transmission>
  <transmission name="index_proximal_trans">
    <type>transmission_interface/SimpleTransmission</type>
    <joint name="right_hand_Index_Finger_Proximal">
      <hardwareInterface>hardware_interface/EffortJointInterface</hardwareInterface>
    </joint>
    <actuator name="index_proximal_motor">
      <mechanicalReduction>1</mechanicalReduction>
    </actuator>
  </transmission>
  <transmission name="middle_proximal_trans">
    <type>transmission_interface/SimpleTransmission</type>
    <joint name="right_hand_Middle_Finger_Proximal">
      <hardwareInterface>hardware_interface/EffortJointInterface</hardwareInterface>
    </joint>
    <actuator name="middle_proximal_motor">
      <mechanicalReduction>1</mechanicalReduction>
    </actuator>
  </transmission>
  <transmission name="middle_distal_trans">
    <type>transmission_interface/SimpleTransmission</type>
    <joint name="right_hand_Middle_Finger_Distal">
      <hardwareInterface>hardware_interface/EffortJointInterface</hardwareInterface>
    </joint>
    <actuator name="middle_distal_motor">
      <mechanicalReduction>1</mechanicalReduction>
    </actuator>
  </transmission>
  <transmission name="ring_trans">
    <type>transmission_interface/SimpleTransmission</type>
    <joint name="right_hand_Ring_Finger">
      <hardwareInterface>hardware_interface/EffortJointInterface</hardwareInterface>
    </joint>
    <actuator name="ring_motor">
      <mechanicalReduction>1</mechanicalReduction>
    </actuator>
  </transmission>
  <transmission name="pinky_trans">
    <type>transmission_interface/SimpleTransmission</type>
    <joint name="right_hand_Pinky">
      <hardwareInterface>hardware_interface/EffortJointInterface</hardwareInterface>
    </joint>
    <actuator name="pinky_motor">
      <mechanicalReduction>1</mechanicalReduction>
    </actuator>
  </transmission>
  <transmission name="spread_trans">
    <type>transmission_interface/SimpleTransmission</type>
    <joint name="right_hand_Finger_Spread">
      <hardwareInterface>hardware_interface/EffortJointInterface</hardwareInterface>
    </joint>
    <actuator name="spread_motor">
      <mechanicalReduction>1</mechanicalReduction>
    </actuator>
  </transmission>
  <gazebo>
    <plugin filename="libgazebo_ros_f3d.so" name="gazebo_ros_f3d">
      <bodyName>right_hand_t</bodyName>
      <topicName>right_hand_t_f3d</topicName>
      <frameName>right_hand_t</frameName>
    </plugin>
  </gazebo>
</robot>

